MuSe-LSTM-Attention-baseline-model/emotion_recognition/main_calibration.py --feature_set bert-4 --emo_dim_set valence --epochs 1 --refresh --n_seeds 1 --seed 314 --predict --attn --rnn_bi --loss ccc --uncertainty_approach monte_carlo_dropout --attn_dr .3 --out_dr .3
Constructing dataset and data loader ...
Constructing data from scratch ...
Found cached annotator 2 video mapping.
Constructing data from scratch ...
No label preprocessing (min -0.6726, max 1.0).
Found cached annotator 2 video mapping.
Constructing data from scratch ...
No label preprocessing (min -1.0, max 1.0).
Found cached annotator 2 video mapping.
Constructing data from scratch ...
No label preprocessing (min -0.7353, max 0.80704).
Found cached annotator 2 video mapping.
Constructing data from scratch ...
No label preprocessing (min -0.9549, max 1.0).
Found cached annotator 2 video mapping.
Constructing data from scratch ...
No label preprocessing (min -0.9706, max 0.9218999999999999).
Found cached annotator 2 video mapping.
Constructing data from scratch ...
No label preprocessing (min -0.39030000000000004, max 0.4687).
Found cached annotator 2 video mapping.
Constructing data from scratch ...
No label preprocessing (min -0.98725, max 1.0).
Found cached annotator 2 video mapping.
Constructing data from scratch ...
No label preprocessing (min -0.8137000000000001, max 1.0).
Found cached annotator 2 video mapping.
Constructing data from scratch ...
Exception for annotator 9: 9
Found cached annotator 2 video mapping.
Constructing data from scratch ...
Exception for annotator 10: 10
Found cached annotator 2 video mapping.
Constructing data from scratch ...
Exception for annotator 11: 11
Found cached annotator 2 video mapping.
Constructing data from scratch ...
Exception for annotator 12: 12
Found cached annotator 2 video mapping.
Constructing data from scratch ...
Exception for annotator 13: 13
Found cached annotator 2 video mapping.
Constructing data from scratch ...
Exception for annotator 14: 14
Found cached annotator 2 video mapping.
Constructing data from scratch ...
No label preprocessing (min -0.58476, max 1.0).
Found cached annotator 2 video mapping.
Constructing data from scratch ...
Exception for annotator 16: 16
Found cached annotator 2 video mapping.
Constructing data from scratch ...
Exception for annotator 17: 17
Samples in partitions: (3122, 62, 64)
Input feature dim: 768.
==================================================
Training model... [seed 314]
Traceback (most recent call last):
  File "/usr/local/lib/python3.7/multiprocessing/util.py", line 265, in _run_finalizers
    finalizer()
  File "/usr/local/lib/python3.7/multiprocessing/util.py", line 189, in __call__
    res = self._callback(*self._args, **self._kwargs)
  File "/usr/local/lib/python3.7/shutil.py", line 485, in rmtree
    _rmtree_safe_fd(fd, path, onerror)
  File "/usr/local/lib/python3.7/shutil.py", line 443, in _rmtree_safe_fd
    onerror(os.unlink, fullname, sys.exc_info())
  File "/usr/local/lib/python3.7/shutil.py", line 441, in _rmtree_safe_fd
    os.unlink(entry.name, dir_fd=topfd)
OSError: [Errno 16] Device or resource busy: '.nfs00000000003a019c000d8f27'
Traceback (most recent call last):
  File "/usr/local/lib/python3.7/multiprocessing/util.py", line 265, in _run_finalizers
    finalizer()
  File "/usr/local/lib/python3.7/multiprocessing/util.py", line 189, in __call__
    res = self._callback(*self._args, **self._kwargs)
  File "/usr/local/lib/python3.7/shutil.py", line 485, in rmtree
    _rmtree_safe_fd(fd, path, onerror)
  File "/usr/local/lib/python3.7/shutil.py", line 443, in _rmtree_safe_fd
    onerror(os.unlink, fullname, sys.exc_info())
  File "/usr/local/lib/python3.7/shutil.py", line 441, in _rmtree_safe_fd
    os.unlink(entry.name, dir_fd=topfd)
OSError: [Errno 16] Device or resource busy: '.nfs00000000003a01a5000d8f26'
Traceback (most recent call last):
  File "/usr/local/lib/python3.7/multiprocessing/util.py", line 265, in _run_finalizers
    finalizer()
  File "/usr/local/lib/python3.7/multiprocessing/util.py", line 189, in __call__
    res = self._callback(*self._args, **self._kwargs)
  File "/usr/local/lib/python3.7/shutil.py", line 485, in rmtree
    _rmtree_safe_fd(fd, path, onerror)
  File "/usr/local/lib/python3.7/shutil.py", line 443, in _rmtree_safe_fd
    onerror(os.unlink, fullname, sys.exc_info())
  File "/usr/local/lib/python3.7/shutil.py", line 441, in _rmtree_safe_fd
    os.unlink(entry.name, dir_fd=topfd)
OSError: [Errno 16] Device or resource busy: '.nfs00000000003a019d000d8f28'
Traceback (most recent call last):
  File "/usr/local/lib/python3.7/multiprocessing/util.py", line 265, in _run_finalizers
    finalizer()
  File "/usr/local/lib/python3.7/multiprocessing/util.py", line 189, in __call__
    res = self._callback(*self._args, **self._kwargs)
  File "/usr/local/lib/python3.7/shutil.py", line 485, in rmtree
    _rmtree_safe_fd(fd, path, onerror)
  File "/usr/local/lib/python3.7/shutil.py", line 443, in _rmtree_safe_fd
    onerror(os.unlink, fullname, sys.exc_info())
  File "/usr/local/lib/python3.7/shutil.py", line 441, in _rmtree_safe_fd
    os.unlink(entry.name, dir_fd=topfd)
OSError: [Errno 16] Device or resource busy: '.nfs00000000003a019f000d8f29'
Traceback (most recent call last):
  File "/usr/local/lib/python3.7/multiprocessing/util.py", line 265, in _run_finalizers
    finalizer()
  File "/usr/local/lib/python3.7/multiprocessing/util.py", line 189, in __call__
    res = self._callback(*self._args, **self._kwargs)
  File "/usr/local/lib/python3.7/shutil.py", line 485, in rmtree
    _rmtree_safe_fd(fd, path, onerror)
  File "/usr/local/lib/python3.7/shutil.py", line 443, in _rmtree_safe_fd
    onerror(os.unlink, fullname, sys.exc_info())
  File "/usr/local/lib/python3.7/shutil.py", line 441, in _rmtree_safe_fd
    os.unlink(entry.name, dir_fd=topfd)
OSError: [Errno 16] Device or resource busy: '.nfs00000000003a01a5000d8f2c'
Traceback (most recent call last):
  File "/usr/local/lib/python3.7/multiprocessing/util.py", line 265, in _run_finalizers
    finalizer()
  File "/usr/local/lib/python3.7/multiprocessing/util.py", line 189, in __call__
    res = self._callback(*self._args, **self._kwargs)
  File "/usr/local/lib/python3.7/shutil.py", line 485, in rmtree
    _rmtree_safe_fd(fd, path, onerror)
  File "/usr/local/lib/python3.7/shutil.py", line 443, in _rmtree_safe_fd
    onerror(os.unlink, fullname, sys.exc_info())
  File "/usr/local/lib/python3.7/shutil.py", line 441, in _rmtree_safe_fd
    os.unlink(entry.name, dir_fd=topfd)
OSError: [Errno 16] Device or resource busy: '.nfs00000000003a019d000d8f2a'
Traceback (most recent call last):
  File "/usr/local/lib/python3.7/multiprocessing/util.py", line 265, in _run_finalizers
    finalizer()
  File "/usr/local/lib/python3.7/multiprocessing/util.py", line 189, in __call__
    res = self._callback(*self._args, **self._kwargs)
  File "/usr/local/lib/python3.7/shutil.py", line 485, in rmtree
    _rmtree_safe_fd(fd, path, onerror)
  File "/usr/local/lib/python3.7/shutil.py", line 443, in _rmtree_safe_fd
    onerror(os.unlink, fullname, sys.exc_info())
  File "/usr/local/lib/python3.7/shutil.py", line 441, in _rmtree_safe_fd
    os.unlink(entry.name, dir_fd=topfd)
OSError: [Errno 16] Device or resource busy: '.nfs00000000003a01d7000d8f2b'
Traceback (most recent call last):
  File "/usr/local/lib/python3.7/multiprocessing/util.py", line 265, in _run_finalizers
    finalizer()
  File "/usr/local/lib/python3.7/multiprocessing/util.py", line 189, in __call__
    res = self._callback(*self._args, **self._kwargs)
  File "/usr/local/lib/python3.7/shutil.py", line 485, in rmtree
    _rmtree_safe_fd(fd, path, onerror)
  File "/usr/local/lib/python3.7/shutil.py", line 443, in _rmtree_safe_fd
    onerror(os.unlink, fullname, sys.exc_info())
  File "/usr/local/lib/python3.7/shutil.py", line 441, in _rmtree_safe_fd
    os.unlink(entry.name, dir_fd=topfd)
OSError: [Errno 16] Device or resource busy: '.nfs00000000003a01a8000d8f2d'
Seed 314 | Best [Val CCC]: 0.1594 [' 0.1594']| Loss: 0.8540 | PCC: 0.1640 ['0.1640'] | RMSE: 0.5667 ['0.5667']
Traceback (most recent call last):
  File "/usr/local/lib/python3.7/multiprocessing/util.py", line 265, in _run_finalizers
    finalizer()
  File "/usr/local/lib/python3.7/multiprocessing/util.py", line 189, in __call__
    res = self._callback(*self._args, **self._kwargs)
  File "/usr/local/lib/python3.7/shutil.py", line 485, in rmtree
    _rmtree_safe_fd(fd, path, onerror)
  File "/usr/local/lib/python3.7/shutil.py", line 443, in _rmtree_safe_fd
    onerror(os.unlink, fullname, sys.exc_info())
  File "/usr/local/lib/python3.7/shutil.py", line 441, in _rmtree_safe_fd
    os.unlink(entry.name, dir_fd=topfd)
OSError: [Errno 16] Device or resource busy: '.nfs00000000003a02e8000d8f31'
Traceback (most recent call last):
  File "/usr/local/lib/python3.7/multiprocessing/util.py", line 265, in _run_finalizers
    finalizer()
  File "/usr/local/lib/python3.7/multiprocessing/util.py", line 189, in __call__
    res = self._callback(*self._args, **self._kwargs)
  File "/usr/local/lib/python3.7/shutil.py", line 485, in rmtree
    _rmtree_safe_fd(fd, path, onerror)
  File "/usr/local/lib/python3.7/shutil.py", line 443, in _rmtree_safe_fd
    onerror(os.unlink, fullname, sys.exc_info())
  File "/usr/local/lib/python3.7/shutil.py", line 441, in _rmtree_safe_fd
    os.unlink(entry.name, dir_fd=topfd)
OSError: [Errno 16] Device or resource busy: '.nfs00000000003a029c000d8f2e'
Traceback (most recent call last):
  File "/usr/local/lib/python3.7/multiprocessing/util.py", line 265, in _run_finalizers
    finalizer()
  File "/usr/local/lib/python3.7/multiprocessing/util.py", line 189, in __call__
    res = self._callback(*self._args, **self._kwargs)
  File "/usr/local/lib/python3.7/shutil.py", line 485, in rmtree
    _rmtree_safe_fd(fd, path, onerror)
  File "/usr/local/lib/python3.7/shutil.py", line 443, in _rmtree_safe_fd
    onerror(os.unlink, fullname, sys.exc_info())
  File "/usr/local/lib/python3.7/shutil.py", line 441, in _rmtree_safe_fd
    os.unlink(entry.name, dir_fd=topfd)
OSError: [Errno 16] Device or resource busy: '.nfs00000000003a01d7000d8f2f'
Traceback (most recent call last):
  File "/usr/local/lib/python3.7/multiprocessing/util.py", line 265, in _run_finalizers
    finalizer()
  File "/usr/local/lib/python3.7/multiprocessing/util.py", line 189, in __call__
    res = self._callback(*self._args, **self._kwargs)
  File "/usr/local/lib/python3.7/shutil.py", line 485, in rmtree
    _rmtree_safe_fd(fd, path, onerror)
  File "/usr/local/lib/python3.7/shutil.py", line 443, in _rmtree_safe_fd
    onerror(os.unlink, fullname, sys.exc_info())
  File "/usr/local/lib/python3.7/shutil.py", line 441, in _rmtree_safe_fd
    os.unlink(entry.name, dir_fd=topfd)
OSError: [Errno 16] Device or resource busy: '.nfs00000000003a02e6000d8f30'
Traceback (most recent call last):
  File "/usr/local/lib/python3.7/multiprocessing/util.py", line 265, in _run_finalizers
    finalizer()
  File "/usr/local/lib/python3.7/multiprocessing/util.py", line 189, in __call__
    res = self._callback(*self._args, **self._kwargs)
  File "/usr/local/lib/python3.7/shutil.py", line 485, in rmtree
    _rmtree_safe_fd(fd, path, onerror)
  File "/usr/local/lib/python3.7/shutil.py", line 443, in _rmtree_safe_fd
    onerror(os.unlink, fullname, sys.exc_info())
  File "/usr/local/lib/python3.7/shutil.py", line 441, in _rmtree_safe_fd
    os.unlink(entry.name, dir_fd=topfd)
OSError: [Errno 16] Device or resource busy: '.nfs00000000003a02ec000d8f34'
Traceback (most recent call last):
  File "/usr/local/lib/python3.7/multiprocessing/util.py", line 265, in _run_finalizers
    finalizer()
  File "/usr/local/lib/python3.7/multiprocessing/util.py", line 189, in __call__
    res = self._callback(*self._args, **self._kwargs)
  File "/usr/local/lib/python3.7/shutil.py", line 485, in rmtree
    _rmtree_safe_fd(fd, path, onerror)
  File "/usr/local/lib/python3.7/shutil.py", line 443, in _rmtree_safe_fd
    onerror(os.unlink, fullname, sys.exc_info())
  File "/usr/local/lib/python3.7/shutil.py", line 441, in _rmtree_safe_fd
    os.unlink(entry.name, dir_fd=topfd)
OSError: [Errno 16] Device or resource busy: '.nfs00000000003a02ea000d8f35'
Traceback (most recent call last):
  File "/usr/local/lib/python3.7/multiprocessing/util.py", line 265, in _run_finalizers
    finalizer()
  File "/usr/local/lib/python3.7/multiprocessing/util.py", line 189, in __call__
    res = self._callback(*self._args, **self._kwargs)
  File "/usr/local/lib/python3.7/shutil.py", line 485, in rmtree
    _rmtree_safe_fd(fd, path, onerror)
  File "/usr/local/lib/python3.7/shutil.py", line 443, in _rmtree_safe_fd
    onerror(os.unlink, fullname, sys.exc_info())
  File "/usr/local/lib/python3.7/shutil.py", line 441, in _rmtree_safe_fd
    os.unlink(entry.name, dir_fd=topfd)
OSError: [Errno 16] Device or resource busy: '.nfs00000000003a029c000d8f33'
Traceback (most recent call last):
  File "/usr/local/lib/python3.7/multiprocessing/util.py", line 265, in _run_finalizers
    finalizer()
  File "/usr/local/lib/python3.7/multiprocessing/util.py", line 189, in __call__
    res = self._callback(*self._args, **self._kwargs)
  File "/usr/local/lib/python3.7/shutil.py", line 485, in rmtree
    _rmtree_safe_fd(fd, path, onerror)
  File "/usr/local/lib/python3.7/shutil.py", line 443, in _rmtree_safe_fd
    onerror(os.unlink, fullname, sys.exc_info())
  File "/usr/local/lib/python3.7/shutil.py", line 441, in _rmtree_safe_fd
    os.unlink(entry.name, dir_fd=topfd)
OSError: [Errno 16] Device or resource busy: '.nfs00000000003a02e9000d8f32'
Traceback (most recent call last):
  File "MuSe-LSTM-Attention-baseline-model/emotion_recognition/main_calibration.py", line 323, in <module>
    main(params)
  File "MuSe-LSTM-Attention-baseline-model/emotion_recognition/main_calibration.py", line 225, in main
    ence_uncal, ence_cal, cv_uncal, cv_cal = calibration_utilities.evaluate_calibration(model, data_loader["test"], data_loader["devel"], params)
  File "/nas/student/NicolasKolbenschlag/emotion_uncertainty_bachelorarbeit/MuSe-LSTM-Attention-baseline-model/emotion_recognition/calibration_utilities.py", line 256, in evaluate_calibration
    full_means, full_vars, full_labels, full_subjectivities, full_means_val, full_vars_val, full_labels_val, full_subjectivities_val = outputs_mc_dropout(model, test_loader, val_loader, params)
  File "/nas/student/NicolasKolbenschlag/emotion_uncertainty_bachelorarbeit/MuSe-LSTM-Attention-baseline-model/emotion_recognition/calibration_utilities.py", line 147, in outputs_mc_dropout
    for i_emo_dim in range(vars_of_sample.shape[1]):
IndexError: tuple index out of range
