/nas/student/NicolasKolbenschlag/emotion_uncertainty_bachelorarbeit/MuSe-LSTM-Attention-baseline-model/emotion_recognition/main_uncertainty_ensemble.py --feature_set bert-4 --emo_dim_set valence --epochs 100 --refresh --n_seeds 5 --seed 314 --attn --rnn_bi --loss ccc --uncertainty_approach ensemble_averaging --attn_dr .5 --out_dr .5 --rnn_n_layers 2 --rnn_dr .5 --measure_uncertainty_globally --global_uncertainty_window 20 --normalize_uncalibrated_global_uncertainty_measurement
Constructing dataset and data loader ...
Constructing data from scratch ...
Calculating subjectivities among annotators from sratch...
Found cached annotator 2 video mapping.
Constructing data from scratch ...
No label preprocessing (min -0.6726, max 1.0).
Found cached annotator 2 video mapping.
Constructing data from scratch ...
No label preprocessing (min -1.0, max 1.0).
Found cached annotator 2 video mapping.
Constructing data from scratch ...
No label preprocessing (min -0.7353, max 0.80704).
Found cached annotator 2 video mapping.
Constructing data from scratch ...
No label preprocessing (min -0.9549, max 1.0).
Found cached annotator 2 video mapping.
Constructing data from scratch ...
No label preprocessing (min -0.9706, max 0.9218999999999999).
Found cached annotator 2 video mapping.
Constructing data from scratch ...
No label preprocessing (min -0.39030000000000004, max 0.4687).
Found cached annotator 2 video mapping.
Constructing data from scratch ...
No label preprocessing (min -0.98725, max 1.0).
Found cached annotator 2 video mapping.
Constructing data from scratch ...
No label preprocessing (min -0.8137000000000001, max 1.0).
Found cached annotator 2 video mapping.
Constructing data from scratch ...
Exception for annotator 9: 9
Found cached annotator 2 video mapping.
Constructing data from scratch ...
Exception for annotator 10: 10
Found cached annotator 2 video mapping.
Constructing data from scratch ...
Exception for annotator 11: 11
Found cached annotator 2 video mapping.
Constructing data from scratch ...
Exception for annotator 12: 12
Found cached annotator 2 video mapping.
Constructing data from scratch ...
Exception for annotator 13: 13
Found cached annotator 2 video mapping.
Constructing data from scratch ...
Exception for annotator 14: 14
Found cached annotator 2 video mapping.
Constructing data from scratch ...
No label preprocessing (min -0.58476, max 1.0).
Found cached annotator 2 video mapping.
Constructing data from scratch ...
Exception for annotator 16: 16
Found cached annotator 2 video mapping.
Constructing data from scratch ...
Exception for annotator 17: 17
Subjectivities calculated.
Samples in partitions: (3132, 62, 64)
Input feature dim: 768.
==================================================
Training model... [seed 314]
/nas/student/NicolasKolbenschlag/emotion_uncertainty_bachelorarbeit/MuSe-LSTM-Attention-baseline-model/emotion_recognition/uncertainty_utilities.py:253: RuntimeWarning: invalid value encountered in double_scalars
  ccc = 2. * covariance / (x_var + y_var + (x_mean - y_mean) ** 2)
Note: target can not be optimized for 15 consecutive epochs, early stop the training process!
Seed 314 | Best [Val CCC]: 0.4312 [' 0.4312']| Loss: 0.6175 | PCC: 0.4429 ['0.4429'] | RMSE: 0.1844 ['0.1844']
On Test: CCC  0.5993 | PCC  0.6123 | RMSE  0.1657
==================================================
Training model... [seed 315]
Note: target can not be optimized for 15 consecutive epochs, early stop the training process!
Seed 315 | Best [Val CCC]: 0.4431 [' 0.4431']| Loss: 0.6209 | PCC: 0.4516 ['0.4516'] | RMSE: 0.1921 ['0.1921']
On Test: CCC  0.6043 | PCC  0.6123 | RMSE  0.1572
==================================================
Training model... [seed 316]
 '.nfs00000000036c0073000004a4'
 '.nfs00000000036c0073000004a7'
 '.nfs00000000036c0072000004a9'
 '.nfs00000000036c0071000004a8'
 '.nfs00000000036c0070000004a7'
Traceback (most recent call last):
  File "/usr/local/lib/python3.7/multiprocessing/util.py", line 265, in _run_finalizers
    finalizer()
  File "/usr/local/lib/python3.7/multiprocessing/util.py", line 189, in __call__
    res = self._callback(*self._args, **self._kwargs)
  File "/usr/local/lib/python3.7/shutil.py", line 485, in rmtree
    _rmtree_safe_fd(fd, path, onerror)
  File "/usr/local/lib/python3.7/shutil.py", line 443, in _rmtree_safe_fd
    onerror(os.unlink, fullname, sys.exc_info())
  File "/usr/local/lib/python3.7/shutil.py", line 441, in _rmtree_safe_fd
    os.unlink(entry.name, dir_fd=topfd)
OSError: [Errno 16] Device or resource busy: '.nfs00000000036c0070000004ad'
Traceback (most recent call last):
  File "/usr/local/lib/python3.7/multiprocessing/util.py", line 265, in _run_finalizers
    finalizer()
  File "/usr/local/lib/python3.7/multiprocessing/util.py", line 189, in __call__
    res = self._callback(*self._args, **self._kwargs)
  File "/usr/local/lib/python3.7/shutil.py", line 485, in rmtree
    _rmtree_safe_fd(fd, path, onerror)
  File "/usr/local/lib/python3.7/shutil.py", line 443, in _rmtree_safe_fd
    onerror(os.unlink, fullname, sys.exc_info())
  File "/usr/local/lib/python3.7/shutil.py", line 441, in _rmtree_safe_fd
    os.unlink(entry.name, dir_fd=topfd)
OSError: [Errno 16] Device or resource busy: '.nfs00000000036c0073000004ac'
Traceback (most recent call last):
  File "/usr/local/lib/python3.7/multiprocessing/util.py", line 265, in _run_finalizers
    finalizer()
  File "/usr/local/lib/python3.7/multiprocessing/util.py", line 189, in __call__
    res = self._callback(*self._args, **self._kwargs)
  File "/usr/local/lib/python3.7/shutil.py", line 485, in rmtree
    _rmtree_safe_fd(fd, path, onerror)
  File "/usr/local/lib/python3.7/shutil.py", line 443, in _rmtree_safe_fd
    onerror(os.unlink, fullname, sys.exc_info())
  File "/usr/local/lib/python3.7/shutil.py", line 441, in _rmtree_safe_fd
    os.unlink(entry.name, dir_fd=topfd)
OSError: [Errno 16] Device or resource busy: '.nfs00000000036c0071000004aa'
Traceback (most recent call last):
  File "/usr/local/lib/python3.7/multiprocessing/util.py", line 265, in _run_finalizers
    finalizer()
  File "/usr/local/lib/python3.7/multiprocessing/util.py", line 189, in __call__
    res = self._callback(*self._args, **self._kwargs)
  File "/usr/local/lib/python3.7/shutil.py", line 485, in rmtree
    _rmtree_safe_fd(fd, path, onerror)
  File "/usr/local/lib/python3.7/shutil.py", line 443, in _rmtree_safe_fd
    onerror(os.unlink, fullname, sys.exc_info())
  File "/usr/local/lib/python3.7/shutil.py", line 441, in _rmtree_safe_fd
    os.unlink(entry.name, dir_fd=topfd)
OSError: [Errno 16] Device or resource busy: '.nfs00000000036c0072000004ab'
Traceback (most recent call last):
  File "/usr/local/lib/python3.7/multiprocessing/util.py", line 265, in _run_finalizers
    finalizer()
  File "/usr/local/lib/python3.7/multiprocessing/util.py", line 189, in __call__
    res = self._callback(*self._args, **self._kwargs)
  File "/usr/local/lib/python3.7/shutil.py", line 485, in rmtree
    _rmtree_safe_fd(fd, path, onerror)
  File "/usr/local/lib/python3.7/shutil.py", line 443, in _rmtree_safe_fd
    onerror(os.unlink, fullname, sys.exc_info())
  File "/usr/local/lib/python3.7/shutil.py", line 441, in _rmtree_safe_fd
    os.unlink(entry.name, dir_fd=topfd)
OSError: [Errno 16] Device or resource busy: '.nfs00000000036c0070000004ae'
Traceback (most recent call last):
  File "/usr/local/lib/python3.7/multiprocessing/util.py", line 265, in _run_finalizers
    finalizer()
  File "/usr/local/lib/python3.7/multiprocessing/util.py", line 189, in __call__
    res = self._callback(*self._args, **self._kwargs)
  File "/usr/local/lib/python3.7/shutil.py", line 485, in rmtree
    _rmtree_safe_fd(fd, path, onerror)
  File "/usr/local/lib/python3.7/shutil.py", line 443, in _rmtree_safe_fd
    onerror(os.unlink, fullname, sys.exc_info())
  File "/usr/local/lib/python3.7/shutil.py", line 441, in _rmtree_safe_fd
    os.unlink(entry.name, dir_fd=topfd)
OSError: [Errno 16] Device or resource busy: '.nfs00000000036c0072000004b0'
Traceback (most recent call last):
  File "/usr/local/lib/python3.7/multiprocessing/util.py", line 265, in _run_finalizers
    finalizer()
  File "/usr/local/lib/python3.7/multiprocessing/util.py", line 189, in __call__
    res = self._callback(*self._args, **self._kwargs)
  File "/usr/local/lib/python3.7/shutil.py", line 485, in rmtree
    _rmtree_safe_fd(fd, path, onerror)
  File "/usr/local/lib/python3.7/shutil.py", line 443, in _rmtree_safe_fd
    onerror(os.unlink, fullname, sys.exc_info())
  File "/usr/local/lib/python3.7/shutil.py", line 441, in _rmtree_safe_fd
    os.unlink(entry.name, dir_fd=topfd)
OSError: [Errno 16] Device or resource busy: '.nfs00000000036c0073000004af'
Traceback (most recent call last):
  File "/usr/local/lib/python3.7/multiprocessing/util.py", line 265, in _run_finalizers
    finalizer()
  File "/usr/local/lib/python3.7/multiprocessing/util.py", line 189, in __call__
    res = self._callback(*self._args, **self._kwargs)
  File "/usr/local/lib/python3.7/shutil.py", line 485, in rmtree
    _rmtree_safe_fd(fd, path, onerror)
  File "/usr/local/lib/python3.7/shutil.py", line 443, in _rmtree_safe_fd
    onerror(os.unlink, fullname, sys.exc_info())
  File "/usr/local/lib/python3.7/shutil.py", line 441, in _rmtree_safe_fd
    os.unlink(entry.name, dir_fd=topfd)
OSError: [Errno 16] Device or resource busy: '.nfs00000000036c0071000004b1'
Traceback (most recent call last):
  File "/usr/local/lib/python3.7/multiprocessing/util.py", line 265, in _run_finalizers
    finalizer()
  File "/usr/local/lib/python3.7/multiprocessing/util.py", line 189, in __call__
    res = self._callback(*self._args, **self._kwargs)
  File "/usr/local/lib/python3.7/shutil.py", line 485, in rmtree
    _rmtree_safe_fd(fd, path, onerror)
  File "/usr/local/lib/python3.7/shutil.py", line 443, in _rmtree_safe_fd
    onerror(os.unlink, fullname, sys.exc_info())
  File "/usr/local/lib/python3.7/shutil.py", line 441, in _rmtree_safe_fd
    os.unlink(entry.name, dir_fd=topfd)
OSError: [Errno 16] Device or resource busy: '.nfs00000000036c0070000004b5'
Traceback (most recent call last):
  File "/usr/local/lib/python3.7/multiprocessing/util.py", line 265, in _run_finalizers
    finalizer()
  File "/usr/local/lib/python3.7/multiprocessing/util.py", line 189, in __call__
    res = self._callback(*self._args, **self._kwargs)
  File "/usr/local/lib/python3.7/shutil.py", line 485, in rmtree
    _rmtree_safe_fd(fd, path, onerror)
  File "/usr/local/lib/python3.7/shutil.py", line 443, in _rmtree_safe_fd
    onerror(os.unlink, fullname, sys.exc_info())
  File "/usr/local/lib/python3.7/shutil.py", line 441, in _rmtree_safe_fd
    os.unlink(entry.name, dir_fd=topfd)
OSError: [Errno 16] Device or resource busy: '.nfs00000000036c0072000004b4'
Traceback (most recent call last):
  File "/usr/local/lib/python3.7/multiprocessing/util.py", line 265, in _run_finalizers
    finalizer()
  File "/usr/local/lib/python3.7/multiprocessing/util.py", line 189, in __call__
    res = self._callback(*self._args, **self._kwargs)
  File "/usr/local/lib/python3.7/shutil.py", line 485, in rmtree
    _rmtree_safe_fd(fd, path, onerror)
  File "/usr/local/lib/python3.7/shutil.py", line 443, in _rmtree_safe_fd
    onerror(os.unlink, fullname, sys.exc_info())
  File "/usr/local/lib/python3.7/shutil.py", line 441, in _rmtree_safe_fd
    os.unlink(entry.name, dir_fd=topfd)
OSError: [Errno 16] Device or resource busy: '.nfs00000000036c0071000004b2'
Traceback (most recent call last):
  File "/usr/local/lib/python3.7/multiprocessing/util.py", line 265, in _run_finalizers
    finalizer()
  File "/usr/local/lib/python3.7/multiprocessing/util.py", line 189, in __call__
    res = self._callback(*self._args, **self._kwargs)
  File "/usr/local/lib/python3.7/shutil.py", line 485, in rmtree
    _rmtree_safe_fd(fd, path, onerror)
  File "/usr/local/lib/python3.7/shutil.py", line 443, in _rmtree_safe_fd
    onerror(os.unlink, fullname, sys.exc_info())
  File "/usr/local/lib/python3.7/shutil.py", line 441, in _rmtree_safe_fd
    os.unlink(entry.name, dir_fd=topfd)
OSError: [Errno 16] Device or resource busy: '.nfs00000000036c0073000004b3'
Traceback (most recent call last):
  File "/usr/local/lib/python3.7/multiprocessing/util.py", line 265, in _run_finalizers
    finalizer()
  File "/usr/local/lib/python3.7/multiprocessing/util.py", line 189, in __call__
    res = self._callback(*self._args, **self._kwargs)
  File "/usr/local/lib/python3.7/shutil.py", line 485, in rmtree
    _rmtree_safe_fd(fd, path, onerror)
  File "/usr/local/lib/python3.7/shutil.py", line 443, in _rmtree_safe_fd
    onerror(os.unlink, fullname, sys.exc_info())
  File "/usr/local/lib/python3.7/shutil.py", line 441, in _rmtree_safe_fd
    os.unlink(entry.name, dir_fd=topfd)
OSError: [Errno 16] Device or resource busy: '.nfs00000000036c0071000004b9'
Traceback (most recent call last):
  File "/usr/local/lib/python3.7/multiprocessing/util.py", line 265, in _run_finalizers
    finalizer()
  File "/usr/local/lib/python3.7/multiprocessing/util.py", line 189, in __call__
    res = self._callback(*self._args, **self._kwargs)
  File "/usr/local/lib/python3.7/shutil.py", line 485, in rmtree
    _rmtree_safe_fd(fd, path, onerror)
  File "/usr/local/lib/python3.7/shutil.py", line 443, in _rmtree_safe_fd
    onerror(os.unlink, fullname, sys.exc_info())
  File "/usr/local/lib/python3.7/shutil.py", line 441, in _rmtree_safe_fd
    os.unlink(entry.name, dir_fd=topfd)
OSError: [Errno 16] Device or resource busy: '.nfs00000000036c0070000004b6'
Traceback (most recent call last):
  File "/usr/local/lib/python3.7/multiprocessing/util.py", line 265, in _run_finalizers
    finalizer()
  File "/usr/local/lib/python3.7/multiprocessing/util.py", line 189, in __call__
    res = self._callback(*self._args, **self._kwargs)
  File "/usr/local/lib/python3.7/shutil.py", line 485, in rmtree
    _rmtree_safe_fd(fd, path, onerror)
  File "/usr/local/lib/python3.7/shutil.py", line 443, in _rmtree_safe_fd
    onerror(os.unlink, fullname, sys.exc_info())
  File "/usr/local/lib/python3.7/shutil.py", line 441, in _rmtree_safe_fd
    os.unlink(entry.name, dir_fd=topfd)
OSError: [Errno 16] Device or resource busy: '.nfs00000000036c0073000004b8'
Traceback (most recent call last):
  File "/usr/local/lib/python3.7/multiprocessing/util.py", line 265, in _run_finalizers
    finalizer()
  File "/usr/local/lib/python3.7/multiprocessing/util.py", line 189, in __call__
    res = self._callback(*self._args, **self._kwargs)
  File "/usr/local/lib/python3.7/shutil.py", line 485, in rmtree
    _rmtree_safe_fd(fd, path, onerror)
  File "/usr/local/lib/python3.7/shutil.py", line 443, in _rmtree_safe_fd
    onerror(os.unlink, fullname, sys.exc_info())
  File "/usr/local/lib/python3.7/shutil.py", line 441, in _rmtree_safe_fd
    os.unlink(entry.name, dir_fd=topfd)
OSError: [Errno 16] Device or resource busy: '.nfs00000000036c0072000004b7'
